Workbook

Sheet ACCUEIL
B1: 🏥 GMAO – Gestion de Maintenance Assistée par Ordinateur
B2: Outil de suivi biomédical – Hôpital
B4: Navigation – Cliquer sur le nom d'un onglet pour y accéder
B5: EQUIPEMENTS | C5: Inventaire du parc biomédical (produits, packages, états)
B6: COMPOSANTS | C6: Composants rattachés à chaque équipement
B7: PACKAGES | C7: Regroupement de produits en packages (ex: pack PC portable)
B8: MAINT_PREV | C8: Planning de maintenance préventive
B9: INTERVENTIONS | C9: Historique de toutes les interventions
B10: FOURNISSEURS | C10: Référentiel fournisseurs / prestataires
B11: PIECES | C11: Stock de pièces détachées et consommables
B12: TECHNICIENS | C12: Référentiel des techniciens biomédicaux
B13: ALERTES | C13: Suivi des non-conformités et équipements critiques
B14: BILANS_GMAO | C14: Tableaux de bord et indicateurs de performance
B15: NOMENCLATURE | C15: Formules, nomenclatures et aide à l'utilisation
B17: Légende des couleurs dans les onglets
C18: Rouge : Équipement critique en panne / alerte urgente
C19: Orange : Maintenance préventive en retard / stock sous minimum
C20: Jaune : Intervention ouverte depuis > 7 jours
C21: Vert : Équipement opérationnel / stock OK
C22: Violet clair : Package (regroupement d'équipements)
B24: ⚠ Texte en rouge italique dans les onglets = champ ou logique ajouté par initiative (non présent dans le document source).

Sheet COMPOSANTS
A1: Code_Composant | B1: Code_Equipement | C1: Designation_Equip | D1: Nom_Composant | E1: Type_Composant | F1: Marque_Composant | G1: Statut_Composant | H1: Date_Detection_Defaut | I1: Action_Requise | J1: Date_Commande | K1: Fournisseur_Piece | L1: Ref_Piece_Commandee | M1: Date_Remplacement | N1: Technicien | O1: Code_Package | P1: Observation
A2: COMP001 | B2: EQ0003 | C2: =IF(B2="","",IFERROR(VLOOKUP(B2,EQUIPEMENTS!A:B,2,0),"")) | D2: Dalle écran | E2: Écran/dalle | F2: LG | G2: Défectueux | H2: 2025-04-20 | I2: Remplacement | J2: 2025-04-21 | K2: FOUR003 | L2: REF-DALLE-HP840 | N2: TECH03 | O2: PKG001 | P2: Dalle cassée - en attente de livraison
A3: COMP002 | B3: EQ0003 | C3: =IF(B3="","",IFERROR(VLOOKUP(B3,EQUIPEMENTS!A:B,2,0),"")) | D3: Batterie | E3: Batterie | F3: HP | G3: Fonctionnel | I3: Aucune | N3: TECH03 | O3: PKG001 | P3: Batterie OK - autonomie correcte
A4: COMP003 | B4: EQ0003 | C4: =IF(B4="","",IFERROR(VLOOKUP(B4,EQUIPEMENTS!A:B,2,0),"")) | D4: Clavier | E4: Clavier | F4: HP | G4: Fonctionnel | I4: Aucune | N4: TECH03 | O4: PKG001 | P4: Clavier OK
A5: COMP004 | B5: EQ0002 | C5: =IF(B5="","",IFERROR(VLOOKUP(B5,EQUIPEMENTS!A:B,2,0),"")) | D5: Filtre principal | E5: Filtre | F5: Invacare | G5: Défectueux | H5: 2025-05-01 | I5: Remplacement | J5: 2025-05-02 | K5: FOUR002 | L5: REF-FILTRE-02 | N5: TECH02 | P5: Encrassé - commande passée
C6: =IF(B6="","",IFERROR(VLOOKUP(B6,EQUIPEMENTS!A:B,2,0),""))
C7: =IF(B7="","",IFERROR(VLOOKUP(B7,EQUIPEMENTS!A:B,2,0),""))
C8: =IF(B8="","",IFERROR(VLOOKUP(B8,EQUIPEMENTS!A:B,2,0),""))
C9: =IF(B9="","",IFERROR(VLOOKUP(B9,EQUIPEMENTS!A:B,2,0),""))
C10: =IF(B10="","",IFERROR(VLOOKUP(B10,EQUIPEMENTS!A:B,2,0),""))
C11: =IF(B11="","",IFERROR(VLOOKUP(B11,EQUIPEMENTS!A:B,2,0),""))
C12: =IF(B12="","",IFERROR(VLOOKUP(B12,EQUIPEMENTS!A:B,2,0),""))
C13: =IF(B13="","",IFERROR(VLOOKUP(B13,EQUIPEMENTS!A:B,2,0),""))
C14: =IF(B14="","",IFERROR(VLOOKUP(B14,EQUIPEMENTS!A:B,2,0),""))
C15: =IF(B15="","",IFERROR(VLOOKUP(B15,EQUIPEMENTS!A:B,2,0),""))
C16: =IF(B16="","",IFERROR(VLOOKUP(B16,EQUIPEMENTS!A:B,2,0),""))
C17: =IF(B17="","",IFERROR(VLOOKUP(B17,EQUIPEMENTS!A:B,2,0),""))
... C500: =IF(B500="","",IFERROR(VLOOKUP(B500,EQUIPEMENTS!A:B,2,0),""))

Sheet LISTES
A1: Criticite | B1: Etat_Equip | C1: Type_Intervention | D1: Statut_Intervention | E1: Statut_MP | F1: Type_MP | G1: Categorie_Equip | H1: Service | I1: Periodicite | J1: Type_Fournisseur | K1: Categorie_Piece | L1: Niveau_Qualification | M1: Statut_Composant | N1: Type_Composant | O1: OuiNon | P1: Priorite
A2: Haute | B2: En service | C2: Corrective | D2: Ouverte | E2: Planifiée | F2: Annuelle | G2: Monitoring | H2: Réanimation | I2: 1 | J2: Fourniture équipement | K2: Batterie | L2: Niveau 1 - Débutant | M2: Fonctionnel | N2: Batterie | O2: Oui | P2: Critique
A3: Moyenne | B3: En panne | C3: Préventive | D3: En cours | E3: En cours | F3: Semestrielle | G3: Imagerie | H3: Urgences | I3: 3 | J3: Maintenance externe | K3: Filtre | L3: Niveau 2 - Technicien | M3: Défectueux | N3: Écran/dalle | O3: Non | P3: Haute
A4: Basse | B4: En maintenance | C4: Contrôle | D4: Clôturée | E4: Réalisée | F4: Trimestrielle | G4: Bloc opératoire | H4: Bloc opératoire | I4: 6 | J4: Calibration | K4: Capteur | L4: Niveau 3 - Expert | M4: Remplacé | N4: Clavier | P4: Normale
B5: Hors service | C5: Installation | D5: Non résolue | E5: Reportée | F5: Contrôle sécurité électrique | G5: Laboratoire | H5: Maternité | I5: 12 | J5: Fourniture consommables | K5: Câble | L5: Niveau 4 - Ingénieur | M5: Commandé | N5: Alimentation externe | P5: Basse
B6: Mis au rebut | C6: Mise au rebut | E6: Annulée | F6: Calibrage | G6: Stérilisation | H6: Laboratoire | I6: 24 | J6: Prestataire informatique | K6: Écran/dalle | M6: En attente | N6: Dock/Station d'accueil
F7: Nettoyage | G7: Informatique | H7: Radiologie | J7: Autre | K7: Clavier | N7: Carte mère
F8: Vérification | G8: Electroménager | H8: Informatique/DSI | K8: Alimentation | N8: CPU/Processeur
G9: Autre | H9: Administration | K9: Carte électronique | N9: Port USB
H10: Autre | K10: Mécanique | N10: Connecteur réseau
K11: Autre | N11: Ventilateur
N12: Disque dur/SSD
N13: Mémoire RAM
N14: Carte graphique
N15: Webcam
N16: Capteur
N17: Filtre
N18: Module radio/WiFi
N19: Autre

Sheet EQUIPEMENTS
A1: Code_Equipement | B1: Designation | C1: Categorie | D1: Criticite | E1: Service | F1: Localisation | G1: Marque | H1: Modele | I1: N_Serie | J1: Date_Acquisition | K1: Fournisseur | L1: Garantie_Fin | M1: Etat | N1: Date_Derniere_Maintenance | O1: Prochaine_Maintenance | P1: Periodicite_Mois | Q1: Technicien_Referent | R1: Code_Package | S1: Nb_Composants | T1: Composant_Defectueux | U1: Observation
A2: EQ0001 | B2: Monitor multiparamétrique | C2: Monitoring | D2: Haute | E2: Réanimation | F2: Bâtiment A - Salle 12 | G2: Philips | H2: IntelliVue MX40 | I2: SN001234 | J2: 2022-03-15 | K2: FOUR001 | L2: 2025-03-15 | M2: En service | N2: 2025-01-10 | O2: 2025-07-10 | P2: 6 | Q2: TECH01 | S2: =COUNTIF(COMPOSANTS!B:B,A2) | T2: =COUNTIFS(COMPOSANTS!B:B,A2,COMPOSANTS!G:G,"Défectueux") | U2: Vérification électrique annuelle OK
A3: EQ0002 | B3: Concentrateur oxygène | C3: Bloc opératoire | D3: Haute | E3: Bloc opératoire | F3: Bâtiment B - Bloc 2 | G3: Invacare | H3: Perfecto2 | I3: SN005678 | J3: 2021-06-01 | K3: FOUR002 | L3: 2024-06-01 | M3: En panne | N3: 2024-12-01 | O3: 2025-06-01 | P3: 6 | Q3: TECH02 | S3: =COUNTIF(COMPOSANTS!B:B,A3) | T3: =COUNTIFS(COMPOSANTS!B:B,A3,COMPOSANTS!G:G,"Défectueux") | U3: Filtre principal encrassé - commande en cours
A4: EQ0003 | B4: Ordi portable HP | C4: Informatique | D4: Moyenne | E4: Informatique/DSI | F4: Bâtiment C - Bureau 5 | G4: HP | H4: EliteBook 840 | I4: SN009012 | J4: 2023-09-01 | K4: FOUR003 | L4: 2026-09-01 | M4: En maintenance | N4: 2025-04-01 | O4: 2025-10-01 | P4: 6 | Q4: TECH03 | R4: PKG001 | S4: =COUNTIF(COMPOSANTS!B:B,A4) | T4: =COUNTIFS(COMPOSANTS!B:B,A4,COMPOSANTS!G:G,"Défectueux") | U4: Dalle défectueuse - en cours de remplacement
A5: EQ0004 | B5: Station d'accueil HP | C5: Informatique | D5: Basse | E5: Informatique/DSI | F5: Bâtiment C - Bureau 5 | G5: HP | H5: Thunderbolt Dock | I5: SN009013 | J5: 2023-09-01 | K5: FOUR003 | L5: 2026-09-01 | M5: En service | N5: 2025-04-01 | O5: 2025-10-01 | P5: 6 | Q5: TECH03 | R5: PKG001 | S5: =COUNTIF(COMPOSANTS!B:B,A5) | T5: =COUNTIFS(COMPOSANTS!B:B,A5,COMPOSANTS!G:G,"Défectueux") | U5: Fait partie du pack PC portable
A6: EQ0005 | B6: Alimentation externe HP | C6: Informatique | D6: Basse | E6: Informatique/DSI | F6: Bâtiment C - Bureau 5 | G6: HP | H6: 65W USB-C | I6: SN009014 | J6: 2023-09-01 | K6: FOUR003 | L6: 2026-09-01 | M6: En service | N6: 2025-04-01 | O6: 2025-10-01 | P6: 6 | Q6: TECH03 | R6: PKG001 | S6: =COUNTIF(COMPOSANTS!B:B,A6) | T6: =COUNTIFS(COMPOSANTS!B:B,A6,COMPOSANTS!G:G,"Défectueux") | U6: Fait partie du pack PC portable
S7: =COUNTIF(COMPOSANTS!B:B,A7) | T7: =COUNTIFS(COMPOSANTS!B:B,A7,COMPOSANTS!G:G,"Défectueux")
S8: =COUNTIF(COMPOSANTS!B:B,A8) | T8: =COUNTIFS(COMPOSANTS!B:B,A8,COMPOSANTS!G:G,"Défectueux")
S9: =COUNTIF(COMPOSANTS!B:B,A9) | T9: =COUNTIFS(COMPOSANTS!B:B,A9,COMPOSANTS!G:G,"Défectueux")
S10: =COUNTIF(COMPOSANTS!B:B,A10) | T10: =COUNTIFS(COMPOSANTS!B:B,A10,COMPOSANTS!G:G,"Défectueux")
S11: =COUNTIF(COMPOSANTS!B:B,A11) | T11: =COUNTIFS(COMPOSANTS!B:B,A11,COMPOSANTS!G:G,"Défectueux")
S12: =COUNTIF(COMPOSANTS!B:B,A12) | T12: =COUNTIFS(COMPOSANTS!B:B,A12,COMPOSANTS!G:G,"Défectueux")
S13: =COUNTIF(COMPOSANTS!B:B,A13) | T13: =COUNTIFS(COMPOSANTS!B:B,A13,COMPOSANTS!G:G,"Défectueux")
S14: =COUNTIF(COMPOSANTS!B:B,A14) | T14: =COUNTIFS(COMPOSANTS!B:B,A14,COMPOSANTS!G:G,"Défectueux")
S15: =COUNTIF(COMPOSANTS!B:B,A15) | T15: =COUNTIFS(COMPOSANTS!B:B,A15,COMPOSANTS!G:G,"Défectueux")
S16: =COUNTIF(COMPOSANTS!B:B,A16) | T16: =COUNTIFS(COMPOSANTS!B:B,A16,COMPOSANTS!G:G,"Défectueux")
S17: =COUNTIF(COMPOSANTS!B:B,A17) | T17: =COUNTIFS(COMPOSANTS!B:B,A17,COMPOSANTS!G:G,"Défectueux")
S18: =COUNTIF(COMPOSANTS!B:B,A18) | T18: =COUNTIFS(COMPOSANTS!B:B,A18,COMPOSANTS!G:G,"Défectueux")
... S500: =COUNTIF(COMPOSANTS!B:B,A500) | T500: =COUNTIFS(COMPOSANTS!B:B,A500,COMPOSANTS!G:G,"Défectueux")

Sheet MAINT_PREV
A1: Code_MP | B1: Code_Equipement | C1: Designation | D1: Type_Maintenance | E1: Date_Prevue | F1: Technicien_Assigne | G1: Statut | H1: Date_Realisation | I1: Temps_Passe_Heures | J1: Retard_Jours | K1: Observation
A2: MP0001 | B2: EQ0001 | C2: =IF(B2="","",IFERROR(VLOOKUP(B2,EQUIPEMENTS!A:B,2,0),"")) | D2: Semestrielle | E2: 2025-01-10 | F2: TECH01 | G2: Réalisée | H2: 2025-01-10 | I2: 3 | J2: =IF(AND(G2="Planifiée",E2<TODAY(),H2=""),TODAY()-E2,"") | K2: Maintenance OK - aucune anomalie
A3: MP0002 | B3: EQ0001 | C3: =IF(B3="","",IFERROR(VLOOKUP(B3,EQUIPEMENTS!A:B,2,0),"")) | D3: Semestrielle | E3: 2025-07-10 | F3: TECH01 | G3: Planifiée | J3: =IF(AND(G3="Planifiée",E3<TODAY(),H3=""),TODAY()-E3,"")
A4: MP0003 | B4: EQ0002 | C4: =IF(B4="","",IFERROR(VLOOKUP(B4,EQUIPEMENTS!A:B,2,0),"")) | D4: Annuelle | E4: 2024-12-01 | F4: TECH02 | G4: Réalisée | H4: 2024-12-01 | I4: 4 | J4: =IF(AND(G4="Planifiée",E4<TODAY(),H4=""),TODAY()-E4,"") | K4: Filtre changé
A5: MP0004 | B5: EQ0002 | C5: =IF(B5="","",IFERROR(VLOOKUP(B5,EQUIPEMENTS!A:B,2,0),"")) | D5: Semestrielle | E5: 2025-06-01 | F5: TECH02 | G5: Planifiée | J5: =IF(AND(G5="Planifiée",E5<TODAY(),H5=""),TODAY()-E5,"") | K5: En retard - équipement en panne
C6: =IF(B6="","",IFERROR(VLOOKUP(B6,EQUIPEMENTS!A:B,2,0),"")) | J6: =IF(AND(G6="Planifiée",E6<TODAY(),H6=""),TODAY()-E6,"")
C7: =IF(B7="","",IFERROR(VLOOKUP(B7,EQUIPEMENTS!A:B,2,0),"")) | J7: =IF(AND(G7="Planifiée",E7<TODAY(),H7=""),TODAY()-E7,"")
C8: =IF(B8="","",IFERROR(VLOOKUP(B8,EQUIPEMENTS!A:B,2,0),"")) | J8: =IF(AND(G8="Planifiée",E8<TODAY(),H8=""),TODAY()-E8,"")
C9: =IF(B9="","",IFERROR(VLOOKUP(B9,EQUIPEMENTS!A:B,2,0),"")) | J9: =IF(AND(G9="Planifiée",E9<TODAY(),H9=""),TODAY()-E9,"")
C10: =IF(B10="","",IFERROR(VLOOKUP(B10,EQUIPEMENTS!A:B,2,0),"")) | J10: =IF(AND(G10="Planifiée",E10<TODAY(),H10=""),TODAY()-E10,"")
C11: =IF(B11="","",IFERROR(VLOOKUP(B11,EQUIPEMENTS!A:B,2,0),"")) | J11: =IF(AND(G11="Planifiée",E11<TODAY(),H11=""),TODAY()-E11,"")
C12: =IF(B12="","",IFERROR(VLOOKUP(B12,EQUIPEMENTS!A:B,2,0),"")) | J12: =IF(AND(G12="Planifiée",E12<TODAY(),H12=""),TODAY()-E12,"")
C13: =IF(B13="","",IFERROR(VLOOKUP(B13,EQUIPEMENTS!A:B,2,0),"")) | J13: =IF(AND(G13="Planifiée",E13<TODAY(),H13=""),TODAY()-E13,"")
C14: =IF(B14="","",IFERROR(VLOOKUP(B14,EQUIPEMENTS!A:B,2,0),"")) | J14: =IF(AND(G14="Planifiée",E14<TODAY(),H14=""),TODAY()-E14,"")
C15: =IF(B15="","",IFERROR(VLOOKUP(B15,EQUIPEMENTS!A:B,2,0),"")) | J15: =IF(AND(G15="Planifiée",E15<TODAY(),H15=""),TODAY()-E15,"")
C16: =IF(B16="","",IFERROR(VLOOKUP(B16,EQUIPEMENTS!A:B,2,0),"")) | J16: =IF(AND(G16="Planifiée",E16<TODAY(),H16=""),TODAY()-E16,"")
C17: =IF(B17="","",IFERROR(VLOOKUP(B17,EQUIPEMENTS!A:B,2,0),"")) | J17: =IF(AND(G17="Planifiée",E17<TODAY(),H17=""),TODAY()-E17,"")
... C500: =IF(B500="","",IFERROR(VLOOKUP(B500,EQUIPEMENTS!A:B,2,0),"")) | J500: =IF(AND(G500="Planifiée",E500<TODAY(),H500=""),TODAY()-E500,"")

Sheet PACKAGES
A1: Code_Package | B1: Nom_Package | C1: Description | D1: Service | E1: Technicien_Referent | F1: Date_Creation | G1: Statut_Package | H1: Nb_Equip_Package | I1: Nb_Composants_Def | J1: Observation
A2: PKG001 | B2: Pack PC Portable HP | C2: Station accueil + HP EliteBook 840 + alimentation 65W | D2: Informatique/DSI | E2: TECH03 | F2: 2023-09-01 | G2: Incomplet | H2: =IF(A2="","",COUNTIF(EQUIPEMENTS!R:R,A2)) | I2: =IF(A2="","",COUNTIFS(COMPOSANTS!O:O,A2,COMPOSANTS!G:G,"Défectueux")) | J2: Dalle défectueuse sur le portable
H3: =IF(A3="","",COUNTIF(EQUIPEMENTS!R:R,A3)) | I3: =IF(A3="","",COUNTIFS(COMPOSANTS!O:O,A3,COMPOSANTS!G:G,"Défectueux"))
H4: =IF(A4="","",COUNTIF(EQUIPEMENTS!R:R,A4)) | I4: =IF(A4="","",COUNTIFS(COMPOSANTS!O:O,A4,COMPOSANTS!G:G,"Défectueux"))
H5: =IF(A5="","",COUNTIF(EQUIPEMENTS!R:R,A5)) | I5: =IF(A5="","",COUNTIFS(COMPOSANTS!O:O,A5,COMPOSANTS!G:G,"Défectueux"))
H6: =IF(A6="","",COUNTIF(EQUIPEMENTS!R:R,A6)) | I6: =IF(A6="","",COUNTIFS(COMPOSANTS!O:O,A6,COMPOSANTS!G:G,"Défectueux"))
H7: =IF(A7="","",COUNTIF(EQUIPEMENTS!R:R,A7)) | I7: =IF(A7="","",COUNTIFS(COMPOSANTS!O:O,A7,COMPOSANTS!G:G,"Défectueux"))
H8: =IF(A8="","",COUNTIF(EQUIPEMENTS!R:R,A8)) | I8: =IF(A8="","",COUNTIFS(COMPOSANTS!O:O,A8,COMPOSANTS!G:G,"Défectueux"))
H9: =IF(A9="","",COUNTIF(EQUIPEMENTS!R:R,A9)) | I9: =IF(A9="","",COUNTIFS(COMPOSANTS!O:O,A9,COMPOSANTS!G:G,"Défectueux"))
H10: =IF(A10="","",COUNTIF(EQUIPEMENTS!R:R,A10)) | I10: =IF(A10="","",COUNTIFS(COMPOSANTS!O:O,A10,COMPOSANTS!G:G,"Défectueux"))
H11: =IF(A11="","",COUNTIF(EQUIPEMENTS!R:R,A11)) | I11: =IF(A11="","",COUNTIFS(COMPOSANTS!O:O,A11,COMPOSANTS!G:G,"Défectueux"))
H12: =IF(A12="","",COUNTIF(EQUIPEMENTS!R:R,A12)) | I12: =IF(A12="","",COUNTIFS(COMPOSANTS!O:O,A12,COMPOSANTS!G:G,"Défectueux"))
H13: =IF(A13="","",COUNTIF(EQUIPEMENTS!R:R,A13)) | I13: =IF(A13="","",COUNTIFS(COMPOSANTS!O:O,A13,COMPOSANTS!G:G,"Défectueux"))
H14: =IF(A14="","",COUNTIF(EQUIPEMENTS!R:R,A14)) | I14: =IF(A14="","",COUNTIFS(COMPOSANTS!O:O,A14,COMPOSANTS!G:G,"Défectueux"))
... H200: =IF(A200="","",COUNTIF(EQUIPEMENTS!R:R,A200)) | I200: =IF(A200="","",COUNTIFS(COMPOSANTS!O:O,A200,COMPOSANTS!G:G,"Défectueux"))

Sheet FOURNISSEURS
A1: Code_Fournisseur | B1: Nom_Fournisseur | C1: Type | D1: Contact | E1: Telephone | F1: Email | G1: Contrat | H1: Date_Debut_Contrat | I1: Date_Fin_Contrat | J1: Delai_Livraison_Jours | K1: Observation
A2: FOUR001 | B2: Philips Medical | C2: Maintenance externe | D2: Jean Dupont | E2: 01 23 45 67 89 | F2: jean.dupont@philips.com | G2: Oui | H2: 2022-01-01 | I2: 2026-01-01 | J2: 5 | K2: Contrat maintenance moniteurs
A3: FOUR002 | B3: Invacare France | C3: Fourniture équipement | D3: Marie Martin | E3: 01 98 76 54 32 | F3: marie.martin@invacare.com | G3: Non | J3: 10
A4: FOUR003 | B4: HP France | C4: Prestataire informatique | D4: Paul Bernard | E4: 0800 123 456 | F4: paul.bernard@hp.com | G4: Oui | H4: 2023-01-01 | I4: 2027-01-01 | J4: 3 | K4: Contrat matériel informatique

Sheet INTERVENTIONS
A1: Code_Intervention | B1: Code_Equipement | C1: Designation | D1: Type_Intervention | E1: Origine_Demande | F1: Date_Demande | G1: Date_Intervention | H1: Technicien | I1: Description_Panne | J1: Action_Realisee | K1: Duree_Intervention_H | L1: Statut | M1: Pieces_Utilisees | N1: Code_Composant_Lie | O1: Jours_Ouvert | P1: Observation_Cloture
A2: INT0001 | B2: EQ0002 | C2: =IF(B2="","",IFERROR(VLOOKUP(B2,EQUIPEMENTS!A:B,2,0),"")) | D2: Corrective | E2: Bloc opératoire | F2: 2025-05-01 | G2: 2025-05-01 | H2: TECH02 | I2: Ne filtre plus correctement | J2: Nettoyage et commande filtre | K2: 1 | L2: En cours | M2: FILTRE-01 | N2: COMP004 | O2: =IF(AND(L2<>"Clôturée",F2<>""),TODAY()-F2,"") | P2: Retour prestataire attendu
A3: INT0002 | B3: EQ0003 | C3: =IF(B3="","",IFERROR(VLOOKUP(B3,EQUIPEMENTS!A:B,2,0),"")) | D3: Corrective | E3: Informatique/DSI | F3: 2025-04-20 | G3: 2025-04-20 | H3: TECH03 | I3: Dalle écran cassée | J3: Commande pièce | K3: 0.5 | L3: En cours | M3: DALLE-HP840 | N3: COMP001 | O3: =IF(AND(L3<>"Clôturée",F3<>""),TODAY()-F3,"") | P3: En attente livraison dalle
A4: INT0003 | B4: EQ0001 | C4: =IF(B4="","",IFERROR(VLOOKUP(B4,EQUIPEMENTS!A:B,2,0),"")) | D4: Préventive | E4: Service technique | F4: 2025-01-10 | G4: 2025-01-10 | H4: TECH01 | I4: Maintenance semestrielle | J4: Nettoyage + vérification | K4: 3 | L4: Clôturée | O4: =IF(AND(L4<>"Clôturée",F4<>""),TODAY()-F4,"") | P4: RAS
C5: =IF(B5="","",IFERROR(VLOOKUP(B5,EQUIPEMENTS!A:B,2,0),"")) | O5: =IF(AND(L5<>"Clôturée",F5<>""),TODAY()-F5,"")
C6: =IF(B6="","",IFERROR(VLOOKUP(B6,EQUIPEMENTS!A:B,2,0),"")) | O6: =IF(AND(L6<>"Clôturée",F6<>""),TODAY()-F6,"")
C7: =IF(B7="","",IFERROR(VLOOKUP(B7,EQUIPEMENTS!A:B,2,0),"")) | O7: =IF(AND(L7<>"Clôturée",F7<>""),TODAY()-F7,"")
C8: =IF(B8="","",IFERROR(VLOOKUP(B8,EQUIPEMENTS!A:B,2,0),"")) | O8: =IF(AND(L8<>"Clôturée",F8<>""),TODAY()-F8,"")
C9: =IF(B9="","",IFERROR(VLOOKUP(B9,EQUIPEMENTS!A:B,2,0),"")) | O9: =IF(AND(L9<>"Clôturée",F9<>""),TODAY()-F9,"")
C10: =IF(B10="","",IFERROR(VLOOKUP(B10,EQUIPEMENTS!A:B,2,0),"")) | O10: =IF(AND(L10<>"Clôturée",F10<>""),TODAY()-F10,"")
C11: =IF(B11="","",IFERROR(VLOOKUP(B11,EQUIPEMENTS!A:B,2,0),"")) | O11: =IF(AND(L11<>"Clôturée",F11<>""),TODAY()-F11,"")
C12: =IF(B12="","",IFERROR(VLOOKUP(B12,EQUIPEMENTS!A:B,2,0),"")) | O12: =IF(AND(L12<>"Clôturée",F12<>""),TODAY()-F12,"")
C13: =IF(B13="","",IFERROR(VLOOKUP(B13,EQUIPEMENTS!A:B,2,0),"")) | O13: =IF(AND(L13<>"Clôturée",F13<>""),TODAY()-F13,"")
C14: =IF(B14="","",IFERROR(VLOOKUP(B14,EQUIPEMENTS!A:B,2,0),"")) | O14: =IF(AND(L14<>"Clôturée",F14<>""),TODAY()-F14,"")
C15: =IF(B15="","",IFERROR(VLOOKUP(B15,EQUIPEMENTS!A:B,2,0),"")) | O15: =IF(AND(L15<>"Clôturée",F15<>""),TODAY()-F15,"")
C16: =IF(B16="","",IFERROR(VLOOKUP(B16,EQUIPEMENTS!A:B,2,0),"")) | O16: =IF(AND(L16<>"Clôturée",F16<>""),TODAY()-F16,"")
... C1000: =IF(B1000="","",IFERROR(VLOOKUP(B1000,EQUIPEMENTS!A:B,2,0),"")) | O1000: =IF(AND(L1000<>"Clôturée",F1000<>""),TODAY()-F1000,"")

Sheet TECHNICIENS
A1: Code_Tech | B1: Nom | C1: Prenom | D1: Fonction | E1: Niveau_Qualification | F1: Experience_Annees | G1: Service_Rattachement | H1: Tel | I1: Email | J1: Formations | K1: Charge_Interventions
A2: TECH01 | B2: Martin | C2: Sophie | D2: Technicienne biomédicale | E2: Niveau 3 - Expert | F2: 8 | G2: Réanimation | H2: 06 11 22 33 44 | I2: s.martin@hopital.fr | J2: Formation GMAO 2024 | K2: =IF(A2="","",COUNTIF(INTERVENTIONS!H:H,A2))
A3: TECH02 | B3: Dubois | C3: Marc | D3: Technicien biomédical | E3: Niveau 2 - Technicien | F3: 5 | G3: Bloc opératoire | H3: 06 55 66 77 88 | I3: m.dubois@hopital.fr | J3: Habilitation électrique BR | K3: =IF(A3="","",COUNTIF(INTERVENTIONS!H:H,A3))
A4: TECH03 | B4: Lemaire | C4: Julie | D4: Technicienne informatique | E4: Niveau 3 - Expert | F4: 6 | G4: Informatique/DSI | H4: 06 99 00 11 22 | I4: j.lemaire@hopital.fr | J4: ITIL v4, Certifiée HP | K4: =IF(A4="","",COUNTIF(INTERVENTIONS!H:H,A4))
K5: =IF(A5="","",COUNTIF(INTERVENTIONS!H:H,A5))
K6: =IF(A6="","",COUNTIF(INTERVENTIONS!H:H,A6))
K7: =IF(A7="","",COUNTIF(INTERVENTIONS!H:H,A7))
K8: =IF(A8="","",COUNTIF(INTERVENTIONS!H:H,A8))
K9: =IF(A9="","",COUNTIF(INTERVENTIONS!H:H,A9))
K10: =IF(A10="","",COUNTIF(INTERVENTIONS!H:H,A10))
K11: =IF(A11="","",COUNTIF(INTERVENTIONS!H:H,A11))
K12: =IF(A12="","",COUNTIF(INTERVENTIONS!H:H,A12))
K13: =IF(A13="","",COUNTIF(INTERVENTIONS!H:H,A13))
K14: =IF(A14="","",COUNTIF(INTERVENTIONS!H:H,A14))
K15: =IF(A15="","",COUNTIF(INTERVENTIONS!H:H,A15))
K16: =IF(A16="","",COUNTIF(INTERVENTIONS!H:H,A16))
... K200: =IF(A200="","",COUNTIF(INTERVENTIONS!H:H,A200))

Sheet PIECES
A1: Code_Piece | B1: Designation | C1: Categorie | D1: Equipement_Compatible | E1: Stock_Actuel | F1: Stock_Min | G1: Stock_Max | H1: Fournisseur | I1: Prix_Unitaire | J1: Derniere_Reception | K1: Alerte_Stock | L1: Observation
A2: PC001 | B2: Filtre concentrateur O2 | C2: Filtre | D2: EQ0002 | E2: 2 | F2: 3 | G2: 10 | H2: FOUR002 | I2: 45.00 | J2: 2025-01-15 | K2: =IF(E2="","",IF(E2<F2,"⚠ STOCK BAS","OK"))
A3: PC002 | B3: Dalle écran HP EliteBook | C3: Écran/dalle | D3: EQ0003 | E3: 0 | F3: 1 | G3: 3 | H3: FOUR003 | I3: 180.00 | J3: 2025-04-25 | K3: =IF(E3="","",IF(E3<F3,"⚠ STOCK BAS","OK")) | L3: En commande
A4: PC003 | B4: Batterie monitor Philips | C4: Batterie | D4: EQ0001 | E4: 4 | F4: 2 | G4: 8 | H4: FOUR001 | I4: 75.00 | J4: 2025-03-01 | K4: =IF(E4="","",IF(E4<F4,"⚠ STOCK BAS","OK"))
K5: =IF(E5="","",IF(E5<F5,"⚠ STOCK BAS","OK"))
K6: =IF(E6="","",IF(E6<F6,"⚠ STOCK BAS","OK"))
K7: =IF(E7="","",IF(E7<F7,"⚠ STOCK BAS","OK"))
K8: =IF(E8="","",IF(E8<F8,"⚠ STOCK BAS","OK"))
K9: =IF(E9="","",IF(E9<F9,"⚠ STOCK BAS","OK"))
K10: =IF(E10="","",IF(E10<F10,"⚠ STOCK BAS","OK"))
K11: =IF(E11="","",IF(E11<F11,"⚠ STOCK BAS","OK"))
K12: =IF(E12="","",IF(E12<F12,"⚠ STOCK BAS","OK"))
K13: =IF(E13="","",IF(E13<F13,"⚠ STOCK BAS","OK"))
K14: =IF(E14="","",IF(E14<F14,"⚠ STOCK BAS","OK"))
K15: =IF(E15="","",IF(E15<F15,"⚠ STOCK BAS","OK"))
K16: =IF(E16="","",IF(E16<F16,"⚠ STOCK BAS","OK"))
... K500: =IF(E500="","",IF(E500<F500,"⚠ STOCK BAS","OK"))

Sheet BILANS_GMAO
B1: 📊 BILANS GMAO – Tableaux de bord
B3: 🔧 PARC ÉQUIPEMENTS | D3: 👷 CHARGE PAR TECHNICIEN
B4: Total équipements | C4: =COUNTA(EQUIPEMENTS!A:A)-1 | D4: Technicien | E4: Nb interventions totales
B5: Équipements en service | C5: =COUNTIF(EQUIPEMENTS!M:M,"En service") | D5: =IFERROR(TECHNICIENS!A2,"") | E5: =IF(D5="","",COUNTIF(INTERVENTIONS!H:H,D5))
B6: Équipements en panne | C6: =COUNTIF(EQUIPEMENTS!M:M,"En panne") | D6: =IFERROR(TECHNICIENS!A3,"") | E6: =IF(D6="","",COUNTIF(INTERVENTIONS!H:H,D6))
B7: Équipements critiques en panne | C7: =COUNTIFS(EQUIPEMENTS!M:M,"En panne",EQUIPEMENTS!D:D,"Haute") | D7: =IFERROR(TECHNICIENS!A4,"") | E7: =IF(D7="","",COUNTIF(INTERVENTIONS!H:H,D7))
B8: Criticité Haute | C8: =COUNTIF(EQUIPEMENTS!D:D,"Haute")
B9: Criticité Moyenne | C9: =COUNTIF(EQUIPEMENTS!D:D,"Moyenne")
B10: Criticité Basse | C10: =COUNTIF(EQUIPEMENTS!D:D,"Basse")
B12: 📦 PACKAGES (INITIATIVE)
B13: Total packages | C13: =COUNTA(PACKAGES!A:A)-1
B14: Packages incomplets | C14: =COUNTIF(PACKAGES!G:G,"Incomplet")
B16: 🔩 COMPOSANTS (INITIATIVE)
B17: Total composants suivis | C17: =COUNTA(COMPOSANTS!A:A)-1
B18: Composants défectueux | C18: =COUNTIF(COMPOSANTS!G:G,"Défectueux")
B19: Composants commandés | C19: =COUNTIF(COMPOSANTS!G:G,"Commandé")
B21: 🗓 MAINTENANCE PRÉVENTIVE
B22: MP planifiées | C22: =COUNTIF(MAINT_PREV!G:G,"Planifiée")
B23: MP réalisées | C23: =COUNTIF(MAINT_PREV!G:G,"Réalisée")
B24: MP en retard | C24: =COUNTIFS(MAINT_PREV!G:G,"Planifiée",MAINT_PREV!E:E,"<"&TODAY(),MAINT_PREV!H:H,"")
B25: Taux réalisation MP (%) | C25: =IFERROR(COUNTIF(MAINT_PREV!G:G,"Réalisée")/COUNTA(MAINT_PREV!A:A)*100,0)
B27: 🛠 INTERVENTIONS
B28: Total interventions | C28: =COUNTA(INTERVENTIONS!A:A)-1
B29: Interventions ouvertes | C29: =COUNTIF(INTERVENTIONS!L:L,"Ouverte")
B30: Interventions correctives (mois en cours) | C30: =COUNTIFS(INTERVENTIONS!D:D,"Corrective",INTERVENTIONS!G:G,">="&DATE(YEAR(TODAY()),MONTH(TODAY()),1))
B31: Interventions >14j non clôturées | C31: =COUNTIFS(INTERVENTIONS!L:L,"Ouverte",INTERVENTIONS!F:F,"<"&TODAY()-14)
B33: 📦 STOCK PIÈCES
B34: Pièces sous stock minimum | C34: =COUNTIFS(PIECES!E:E,">"&0,PIECES!E:E,"<"&PIECES!F2)

Sheet ALERTES
A1: Code_Equipement | B1: Designation | C1: Criticite | D1: Etat | E1: Nb_MP_Retard | F1: Nb_Interv_Ouvertes | G1: Nb_Composants_Defectueux | H1: Code_Package | I1: Niveau_Alerte | J1: Technicien_Referent | K1: Observation
A2: =IFERROR(EQUIPEMENTS!A2,"") | B2: =IF(A2="","",IFERROR(VLOOKUP(A2,EQUIPEMENTS!A:B,2,0),"")) | C2: =IF(A2="","",IFERROR(VLOOKUP(A2,EQUIPEMENTS!A:D,4,0),"")) | D2: =IF(A2="","",IFERROR(VLOOKUP(A2,EQUIPEMENTS!A:M,13,0),"")) | E2: =IF(A2="","",COUNTIFS(MAINT_PREV!B:B,A2,MAINT_PREV!G:G,"Planifiée",MAINT_PREV!E:E,"<"&TODAY(),MAINT_PREV!H:H,"")) | F2: =IF(A2="","",COUNTIFS(INTERVENTIONS!B:B,A2,INTERVENTIONS!L:L,"Ouverte")) | G2: =IF(A2="","",COUNTIFS(COMPOSANTS!B:B,A2,COMPOSANTS!G:G,"Défectueux")) | H2: =IF(A2="","",IFERROR(VLOOKUP(A2,EQUIPEMENTS!A:R,18,0),"")) | I2: =IF(A2="","",IF(AND(C2="Haute",D2="En panne"),"🔴 CRITIQUE",IF(OR(E2>0,F2>0,G2>0),"🟠 ATTENTION","🟢 OK"))) | J2: =IF(A2="","",IFERROR(VLOOKUP(A2,EQUIPEMENTS!A:Q,17,0),""))
A3: =IFERROR(EQUIPEMENTS!A3,"") | B3: =IF(A3="","",IFERROR(VLOOKUP(A3,EQUIPEMENTS!A:B,2,0),"")) | C3: =IF(A3="","",IFERROR(VLOOKUP(A3,EQUIPEMENTS!A:D,4,0),"")) | D3: =IF(A3="","",IFERROR(VLOOKUP(A3,EQUIPEMENTS!A:M,13,0),"")) | E3: =IF(A3="","",COUNTIFS(MAINT_PREV!B:B,A3,MAINT_PREV!G:G,"Planifiée",MAINT_PREV!E:E,"<"&TODAY(),MAINT_PREV!H:H,"")) | F3: =IF(A3="","",COUNTIFS(INTERVENTIONS!B:B,A3,INTERVENTIONS!L:L,"Ouverte")) | G3: =IF(A3="","",COUNTIFS(COMPOSANTS!B:B,A3,COMPOSANTS!G:G,"Défectueux")) | H3: =IF(A3="","",IFERROR(VLOOKUP(A3,EQUIPEMENTS!A:R,18,0),"")) | I3: =IF(A3="","",IF(AND(C3="Haute",D3="En panne"),"🔴 CRITIQUE",IF(OR(E3>0,F3>0,G3>0),"🟠 ATTENTION","🟢 OK"))) | J3: =IF(A3="","",IFERROR(VLOOKUP(A3,EQUIPEMENTS!A:Q,17,0),""))
A4: =IFERROR(EQUIPEMENTS!A4,"") | B4: =IF(A4="","",IFERROR(VLOOKUP(A4,EQUIPEMENTS!A:B,2,0),"")) | C4: =IF(A4="","",IFERROR(VLOOKUP(A4,EQUIPEMENTS!A:D,4,0),"")) | D4: =IF(A4="","",IFERROR(VLOOKUP(A4,EQUIPEMENTS!A:M,13,0),"")) | E4: =IF(A4="","",COUNTIFS(MAINT_PREV!B:B,A4,MAINT_PREV!G:G,"Planifiée",MAINT_PREV!E:E,"<"&TODAY(),MAINT_PREV!H:H,"")) | F4: =IF(A4="","",COUNTIFS(INTERVENTIONS!B:B,A4,INTERVENTIONS!L:L,"Ouverte")) | G4: =IF(A4="","",COUNTIFS(COMPOSANTS!B:B,A4,COMPOSANTS!G:G,"Défectueux")) | H4: =IF(A4="","",IFERROR(VLOOKUP(A4,EQUIPEMENTS!A:R,18,0),"")) | I4: =IF(A4="","",IF(AND(C4="Haute",D4="En panne"),"🔴 CRITIQUE",IF(OR(E4>0,F4>0,G4>0),"🟠 ATTENTION","🟢 OK"))) | J4: =IF(A4="","",IFERROR(VLOOKUP(A4,EQUIPEMENTS!A:Q,17,0),""))
A5: =IFERROR(EQUIPEMENTS!A5,"") | B5: =IF(A5="","",IFERROR(VLOOKUP(A5,EQUIPEMENTS!A:B,2,0),"")) | C5: =IF(A5="","",IFERROR(VLOOKUP(A5,EQUIPEMENTS!A:D,4,0),"")) | D5: =IF(A5="","",IFERROR(VLOOKUP(A5,EQUIPEMENTS!A:M,13,0),"")) | E5: =IF(A5="","",COUNTIFS(MAINT_PREV!B:B,A5,MAINT_PREV!G:G,"Planifiée",MAINT_PREV!E:E,"<"&TODAY(),MAINT_PREV!H:H,"")) | F5: =IF(A5="","",COUNTIFS(INTERVENTIONS!B:B,A5,INTERVENTIONS!L:L,"Ouverte")) | G5: =IF(A5="","",COUNTIFS(COMPOSANTS!B:B,A5,COMPOSANTS!G:G,"Défectueux")) | H5: =IF(A5="","",IFERROR(VLOOKUP(A5,EQUIPEMENTS!A:R,18,0),"")) | I5: =IF(A5="","",IF(AND(C5="Haute",D5="En panne"),"🔴 CRITIQUE",IF(OR(E5>0,F5>0,G5>0),"🟠 ATTENTION","🟢 OK"))) | J5: =IF(A5="","",IFERROR(VLOOKUP(A5,EQUIPEMENTS!A:Q,17,0),""))
A6: =IFERROR(EQUIPEMENTS!A6,"") | B6: =IF(A6="","",IFERROR(VLOOKUP(A6,EQUIPEMENTS!A:B,2,0),"")) | C6: =IF(A6="","",IFERROR(VLOOKUP(A6,EQUIPEMENTS!A:D,4,0),"")) | D6: =IF(A6="","",IFERROR(VLOOKUP(A6,EQUIPEMENTS!A:M,13,0),"")) | E6: =IF(A6="","",COUNTIFS(MAINT_PREV!B:B,A6,MAINT_PREV!G:G,"Planifiée",MAINT_PREV!E:E,"<"&TODAY(),MAINT_PREV!H:H,"")) | F6: =IF(A6="","",COUNTIFS(INTERVENTIONS!B:B,A6,INTERVENTIONS!L:L,"Ouverte")) | G6: =IF(A6="","",COUNTIFS(COMPOSANTS!B:B,A6,COMPOSANTS!G:G,"Défectueux")) | H6: =IF(A6="","",IFERROR(VLOOKUP(A6,EQUIPEMENTS!A:R,18,0),"")) | I6: =IF(A6="","",IF(AND(C6="Haute",D6="En panne"),"🔴 CRITIQUE",IF(OR(E6>0,F6>0,G6>0),"🟠 ATTENTION","🟢 OK"))) | J6: =IF(A6="","",IFERROR(VLOOKUP(A6,EQUIPEMENTS!A:Q,17,0),""))
A7: =IFERROR(EQUIPEMENTS!A7,"") | B7: =IF(A7="","",IFERROR(VLOOKUP(A7,EQUIPEMENTS!A:B,2,0),"")) | C7: =IF(A7="","",IFERROR(VLOOKUP(A7,EQUIPEMENTS!A:D,4,0),"")) | D7: =IF(A7="","",IFERROR(VLOOKUP(A7,EQUIPEMENTS!A:M,13,0),"")) | E7: =IF(A7="","",COUNTIFS(MAINT_PREV!B:B,A7,MAINT_PREV!G:G,"Planifiée",MAINT_PREV!E:E,"<"&TODAY(),MAINT_PREV!H:H,"")) | F7: =IF(A7="","",COUNTIFS(INTERVENTIONS!B:B,A7,INTERVENTIONS!L:L,"Ouverte")) | G7: =IF(A7="","",COUNTIFS(COMPOSANTS!B:B,A7,COMPOSANTS!G:G,"Défectueux")) | H7: =IF(A7="","",IFERROR(VLOOKUP(A7,EQUIPEMENTS!A:R,18,0),"")) | I7: =IF(A7="","",IF(AND(C7="Haute",D7="En panne"),"🔴 CRITIQUE",IF(OR(E7>0,F7>0,G7>0),"🟠 ATTENTION","🟢 OK"))) | J7: =IF(A7="","",IFERROR(VLOOKUP(A7,EQUIPEMENTS!A:Q,17,0),""))
A8: =IFERROR(EQUIPEMENTS!A8,"") | B8: =IF(A8="","",IFERROR(VLOOKUP(A8,EQUIPEMENTS!A:B,2,0),"")) | C8: =IF(A8="","",IFERROR(VLOOKUP(A8,EQUIPEMENTS!A:D,4,0),"")) | D8: =IF(A8="","",IFERROR(VLOOKUP(A8,EQUIPEMENTS!A:M,13,0),"")) | E8: =IF(A8="","",COUNTIFS(MAINT_PREV!B:B,A8,MAINT_PREV!G:G,"Planifiée",MAINT_PREV!E:E,"<"&TODAY(),MAINT_PREV!H:H,"")) | F8: =IF(A8="","",COUNTIFS(INTERVENTIONS!B:B,A8,INTERVENTIONS!L:L,"Ouverte")) | G8: =IF(A8="","",COUNTIFS(COMPOSANTS!B:B,A8,COMPOSANTS!G:G,"Défectueux")) | H8: =IF(A8="","",IFERROR(VLOOKUP(A8,EQUIPEMENTS!A:R,18,0),"")) | I8: =IF(A8="","",IF(AND(C8="Haute",D8="En panne"),"🔴 CRITIQUE",IF(OR(E8>0,F8>0,G8>0),"🟠 ATTENTION","🟢 OK"))) | J8: =IF(A8="","",IFERROR(VLOOKUP(A8,EQUIPEMENTS!A:Q,17,0),""))
A9: =IFERROR(EQUIPEMENTS!A9,"") | B9: =IF(A9="","",IFERROR(VLOOKUP(A9,EQUIPEMENTS!A:B,2,0),"")) | C9: =IF(A9="","",IFERROR(VLOOKUP(A9,EQUIPEMENTS!A:D,4,0),"")) | D9: =IF(A9="","",IFERROR(VLOOKUP(A9,EQUIPEMENTS!A:M,13,0),"")) | E9: =IF(A9="","",COUNTIFS(MAINT_PREV!B:B,A9,MAINT_PREV!G:G,"Planifiée",MAINT_PREV!E:E,"<"&TODAY(),MAINT_PREV!H:H,"")) | F9: =IF(A9="","",COUNTIFS(INTERVENTIONS!B:B,A9,INTERVENTIONS!L:L,"Ouverte")) | G9: =IF(A9="","",COUNTIFS(COMPOSANTS!B:B,A9,COMPOSANTS!G:G,"Défectueux")) | H9: =IF(A9="","",IFERROR(VLOOKUP(A9,EQUIPEMENTS!A:R,18,0),"")) | I9: =IF(A9="","",IF(AND(C9="Haute",D9="En panne"),"🔴 CRITIQUE",IF(OR(E9>0,F9>0,G9>0),"🟠 ATTENTION","🟢 OK"))) | J9: =IF(A9="","",IFERROR(VLOOKUP(A9,EQUIPEMENTS!A:Q,17,0),""))
A10: =IFERROR(EQUIPEMENTS!A10,"") | B10: =IF(A10="","",IFERROR(VLOOKUP(A10,EQUIPEMENTS!A:B,2,0),"")) | C10: =IF(A10="","",IFERROR(VLOOKUP(A10,EQUIPEMENTS!A:D,4,0),"")) | D10: =IF(A10="","",IFERROR(VLOOKUP(A10,EQUIPEMENTS!A:M,13,0),"")) | E10: =IF(A10="","",COUNTIFS(MAINT_PREV!B:B,A10,MAINT_PREV!G:G,"Planifiée",MAINT_PREV!E:E,"<"&TODAY(),MAINT_PREV!H:H,"")) | F10: =IF(A10="","",COUNTIFS(INTERVENTIONS!B:B,A10,INTERVENTIONS!L:L,"Ouverte")) | G10: =IF(A10="","",COUNTIFS(COMPOSANTS!B:B,A10,COMPOSANTS!G:G,"Défectueux")) | H10: =IF(A10="","",IFERROR(VLOOKUP(A10,EQUIPEMENTS!A:R,18,0),"")) | I10: =IF(A10="","",IF(AND(C10="Haute",D10="En panne"),"🔴 CRITIQUE",IF(OR(E10>0,F10>0,G10>0),"🟠 ATTENTION","🟢 OK"))) | J10: =IF(A10="","",IFERROR(VLOOKUP(A10,EQUIPEMENTS!A:Q,17,0),""))
A11: =IFERROR(EQUIPEMENTS!A11,"") | B11: =IF(A11="","",IFERROR(VLOOKUP(A11,EQUIPEMENTS!A:B,2,0),"")) | C11: =IF(A11="","",IFERROR(VLOOKUP(A11,EQUIPEMENTS!A:D,4,0),"")) | D11: =IF(A11="","",IFERROR(VLOOKUP(A11,EQUIPEMENTS!A:M,13,0),"")) | E11: =IF(A11="","",COUNTIFS(MAINT_PREV!B:B,A11,MAINT_PREV!G:G,"Planifiée",MAINT_PREV!E:E,"<"&TODAY(),MAINT_PREV!H:H,"")) | F11: =IF(A11="","",COUNTIFS(INTERVENTIONS!B:B,A11,INTERVENTIONS!L:L,"Ouverte")) | G11: =IF(A11="","",COUNTIFS(COMPOSANTS!B:B,A11,COMPOSANTS!G:G,"Défectueux")) | H11: =IF(A11="","",IFERROR(VLOOKUP(A11,EQUIPEMENTS!A:R,18,0),"")) | I11: =IF(A11="","",IF(AND(C11="Haute",D11="En panne"),"🔴 CRITIQUE",IF(OR(E11>0,F11>0,G11>0),"🟠 ATTENTION","🟢 OK"))) | J11: =IF(A11="","",IFERROR(VLOOKUP(A11,EQUIPEMENTS!A:Q,17,0),""))
A12: =IFERROR(EQUIPEMENTS!A12,"") | B12: =IF(A12="","",IFERROR(VLOOKUP(A12,EQUIPEMENTS!A:B,2,0),"")) | C12: =IF(A12="","",IFERROR(VLOOKUP(A12,EQUIPEMENTS!A:D,4,0),"")) | D12: =IF(A12="","",IFERROR(VLOOKUP(A12,EQUIPEMENTS!A:M,13,0),"")) | E12: =IF(A12="","",COUNTIFS(MAINT_PREV!B:B,A12,MAINT_PREV!G:G,"Planifiée",MAINT_PREV!E:E,"<"&TODAY(),MAINT_PREV!H:H,"")) | F12: =IF(A12="","",COUNTIFS(INTERVENTIONS!B:B,A12,INTERVENTIONS!L:L,"Ouverte")) | G12: =IF(A12="","",COUNTIFS(COMPOSANTS!B:B,A12,COMPOSANTS!G:G,"Défectueux")) | H12: =IF(A12="","",IFERROR(VLOOKUP(A12,EQUIPEMENTS!A:R,18,0),"")) | I12: =IF(A12="","",IF(AND(C12="Haute",D12="En panne"),"🔴 CRITIQUE",IF(OR(E12>0,F12>0,G12>0),"🟠 ATTENTION","🟢 OK"))) | J12: =IF(A12="","",IFERROR(VLOOKUP(A12,EQUIPEMENTS!A:Q,17,0),""))
A13: =IFERROR(EQUIPEMENTS!A13,"") | B13: =IF(A13="","",IFERROR(VLOOKUP(A13,EQUIPEMENTS!A:B,2,0),"")) | C13: =IF(A13="","",IFERROR(VLOOKUP(A13,EQUIPEMENTS!A:D,4,0),"")) | D13: =IF(A13="","",IFERROR(VLOOKUP(A13,EQUIPEMENTS!A:M,13,0),"")) | E13: =IF(A13="","",COUNTIFS(MAINT_PREV!B:B,A13,MAINT_PREV!G:G,"Planifiée",MAINT_PREV!E:E,"<"&TODAY(),MAINT_PREV!H:H,"")) | F13: =IF(A13="","",COUNTIFS(INTERVENTIONS!B:B,A13,INTERVENTIONS!L:L,"Ouverte")) | G13: =IF(A13="","",COUNTIFS(COMPOSANTS!B:B,A13,COMPOSANTS!G:G,"Défectueux")) | H13: =IF(A13="","",IFERROR(VLOOKUP(A13,EQUIPEMENTS!A:R,18,0),"")) | I13: =IF(A13="","",IF(AND(C13="Haute",D13="En panne"),"🔴 CRITIQUE",IF(OR(E13>0,F13>0,G13>0),"🟠 ATTENTION","🟢 OK"))) | J13: =IF(A13="","",IFERROR(VLOOKUP(A13,EQUIPEMENTS!A:Q,17,0),""))
... A500: =IFERROR(EQUIPEMENTS!A500,"") | B500: =IF(A500="","",IFERROR(VLOOKUP(A500,EQUIPEMENTS!A:B,2,0),"")) | C500: =IF(A500="","",IFERROR(VLOOKUP(A500,EQUIPEMENTS!A:D,4,0),"")) | D500: =IF(A500="","",IFERROR(VLOOKUP(A500,EQUIPEMENTS!A:M,13,0),"")) | E500: =IF(A500="","",COUNTIFS(MAINT_PREV!B:B,A500,MAINT_PREV!G:G,"Planifiée",MAINT_PREV!E:E,"<"&TODAY(),MAINT_PREV!H:H,"")) | F500: =IF(A500="","",COUNTIFS(INTERVENTIONS!B:B,A500,INTERVENTIONS!L:L,"Ouverte")) | G500: =IF(A500="","",COUNTIFS(COMPOSANTS!B:B,A500,COMPOSANTS!G:G,"Défectueux")) | H500: =IF(A500="","",IFERROR(VLOOKUP(A500,EQUIPEMENTS!A:R,18,0),"")) | I500: =IF(A500="","",IF(AND(C500="Haute",D500="En panne"),"🔴 CRITIQUE",IF(OR(E500>0,F500>0,G500>0),"🟠 ATTENTION","🟢 OK"))) | J500: =IF(A500="","",IFERROR(VLOOKUP(A500,EQUIPEMENTS!A:Q,17,0),""))

Sheet NOMENCLATURE
B1: 📘 NOMENCLATURE – Formules, codes et aide à l'utilisation
B3: CODIFICATION – Préfixes à respecter
B4: Équipements | C4: EQ0001, EQ0002 … (format EQ + 4 chiffres)
B5: Composants | C5: COMP001, COMP002 … (format COMP + 3 chiffres)
B6: Packages | C6: PKG001, PKG002 … (format PKG + 3 chiffres)
B7: Maintenances préventives | C7: MP0001, MP0002 … (format MP + 4 chiffres)
B8: Interventions | C8: INT0001, INT0002 … (format INT + 4 chiffres)
B9: Fournisseurs | C9: FOUR001, FOUR002 … (format FOUR + 3 chiffres)
B10: Pièces | C10: PC001, PC002 … (format PC + 3 chiffres)
B11: Techniciens | C11: TECH01, TECH02 … (format TECH + 2 chiffres)
B13: FORMULES CLÉS – BILANS_GMAO
B14: Total équipements | C14: =COUNTA(EQUIPEMENTS!A:A)-1
B15: Équipements critiques en panne | C15: =COUNTIFS(EQUIPEMENTS!M:M,"En panne",EQUIPEMENTS!D:D,"Haute")
B16: MP en retard | C16: =COUNTIFS(MAINT_PREV!G:G,"Planifiée",MAINT_PREV!E:E,"<"&TODAY(),MAINT_PREV!H:H,"")
B17: Interv. correctives (mois) | C17: =COUNTIFS(INTERVENTIONS!D:D,"Corrective",INTERVENTIONS!G:G,">="&DATE(YEAR(TODAY()),MONTH(TODAY()),1))
B18: Interv. >14j non clôturées | C18: =COUNTIFS(INTERVENTIONS!L:L,"Ouverte",INTERVENTIONS!F:F,"<"&TODAY()-14)
B19: Composants défectueux d'un EQ | C19: =COUNTIFS(COMPOSANTS!B:B,A2,COMPOSANTS!G:G,"Défectueux")
B20: Nb équipements dans un package | C20: =COUNTIF(EQUIPEMENTS!R:R,A2)
B22: FORMULES CLÉS – Colonnes calculées (VLOOKUP / COUNTIF)
B23: Désignation depuis code EQ | C23: =IF(B2="","",IFERROR(VLOOKUP(B2,EQUIPEMENTS!A:B,2,0),""))
B24: Retard MP (jours) | C24: =IF(AND(G2="Planifiée",E2<TODAY(),H2=""),TODAY()-E2,"")
B25: Jours intervention ouverte | C25: =IF(AND(L2<>"Clôturée",F2<>""),TODAY()-F2,"")
B26: Alerte stock pièce | C26: =IF(E2="","",IF(E2<F2,"⚠ STOCK BAS","OK"))
B27: Nb interventions technicien | C27: =IF(A2="","",COUNTIF(INTERVENTIONS!H:H,A2))
B29: MISE EN FORME CONDITIONNELLE – Couleurs
B30: Rouge fond clair | C30: Équipement critique (Haute) en panne – formule: AND($D2="Haute",$M2="En panne")
B31: Orange fond clair | C31: MP en retard / Stock sous minimum / Contrat expirant
B32: Jaune fond | C32: Intervention ouverte depuis >7j – formule: AND($L2<>"Clôturée",TODAY()-$F2>7)
B33: Rouge fond | C33: Intervention ouverte >14j / Stock nul / Contrat expiré
B34: Violet clair | C34: Équipement appartenant à un package ($R2<>"")
B35: Vert clair | C35: Pas d'alerte (🟢 OK dans ALERTES)
B37: ONGLETS INITIATIVE (texte rouge dans les en-têtes)
B38: COMPOSANTS | C38: Onglet entier – gestion des composants défectueux rattachés aux équipements
B39: PACKAGES | C39: Onglet entier – regroupement d'équipements en packages (ex: pack PC)
B40: EQUIPEMENTS!R | C40: Code_Package – lien vers l'onglet PACKAGES
B41: EQUIPEMENTS!S | C41: Nb_Composants – =COUNTIF(COMPOSANTS!B:B,A2)
B42: EQUIPEMENTS!T | C42: Composant_Defectueux – =COUNTIFS(COMPOSANTS!B:B,A2,COMPOSANTS!G:G,"Défectueux")
B43: INTERVENTIONS!N | C43: Code_Composant_Lie – lien entre intervention et composant
B44: INTERVENTIONS!O | C44: Jours_Ouvert – =IF(AND(L2<>"Clôturée",F2<>""),TODAY()-F2,"")
B45: MAINT_PREV!J | C45: Retard_Jours – calcul automatique du retard en jours
...
